<?xml version="1.0" encoding="utf-8"?>
<!-- This URDF was automatically created by SolidWorks to URDF Exporter! Originally created by Stephen Brawner (brawner@gmail.com) 
     Commit Version: 1.6.0-1-g15f4949  Build Version: 1.6.7594.29634
     For more information, please see http://wiki.ros.org/sw_urdf_exporter -->
<robot
  name="hand">
  <link
    name="base_link">
    <inertial>
      <origin
        xyz="0.066267 0.12555 0.14143"
        rpy="0 0 0" />
      <mass
        value="1.744" />
      <inertia
        ixx="0.0058067"
        ixy="1.1646E-05"
        ixz="-0.00013343"
        iyy="0.0096896"
        iyz="5.4081E-07"
        izz="0.0053296" />
    </inertial>
    <visual>
      <origin
        xyz="0 0 0"
        rpy="0 0 0" />
      <geometry>
        <mesh
          filename="package://hand/meshes/base_link.STL" />
      </geometry>
      <material
        name="">
        <color
          rgba="0.79216 0.81961 0.93333 1" />
      </material>
    </visual>
    <collision>
      <origin
        xyz="0 0 0"
        rpy="0 0 0" />
      <geometry>
        <mesh
          filename="package://hand/meshes/base_link.STL" />
      </geometry>
    </collision>
  </link>
  <link
    name="finger1link1">
    <inertial>
      <origin
        xyz="0.045353 -0.015 2.7756E-17"
        rpy="0 0 0" />
      <mass
        value="0.084502" />
      <inertia
        ixx="1.3498E-05"
        ixy="-4.8486E-21"
        ixz="-7.2845E-20"
        iyy="7.9847E-05"
        iyz="-9.218E-22"
        izz="7.9679E-05" />
    </inertial>
    <visual>
      <origin
        xyz="0 0 0"
        rpy="0 0 0" />
      <geometry>
        <mesh
          filename="package://hand/meshes/finger1link1.STL" />
      </geometry>
      <material
        name="">
        <color
          rgba="0.79216 0.81961 0.93333 1" />
      </material>
    </visual>
    <collision>
      <origin
        xyz="0 0 0"
        rpy="0 0 0" />
      <geometry>
        <mesh
          filename="package://hand/meshes/finger1link1.STL" />
      </geometry>
    </collision>
  </link>
  <joint
    name="finger1joint1"
    type="continuous">
    <origin
      xyz="0.14041 -0.20248 0.13064"
      rpy="0 -0.48387 0" />
    <parent
      link="base_link" />
    <child
      link="finger1link1" />
    <axis
      xyz="0 1 0" />
  </joint>
  <link
    name="finger1link2">
    <inertial>
      <origin
        xyz="0.05463 -5.5511E-17 0.008"
        rpy="0 0 0" />
      <mass
        value="0.054283" />
      <inertia
        ixx="5.2686E-06"
        ixy="6.0775E-20"
        ixz="-1.5092E-21"
        iyy="6.3413E-05"
        iyz="3.514E-22"
        izz="6.6365E-05" />
    </inertial>
    <visual>
      <origin
        xyz="0 0 0"
        rpy="0 0 0" />
      <geometry>
        <mesh
          filename="package://hand/meshes/finger1link2.STL" />
      </geometry>
      <material
        name="">
        <color
          rgba="0.79216 0.81961 0.93333 1" />
      </material>
    </visual>
    <collision>
      <origin
        xyz="0 0 0"
        rpy="0 0 0" />
      <geometry>
        <mesh
          filename="package://hand/meshes/finger1link2.STL" />
      </geometry>
    </collision>
  </link>
  <joint
    name="finger1joint2"
    type="continuous">
    <origin
      xyz="0.100000000000001 -0.005 0"
      rpy="1.5707963267949 1.15783000301896 0" />
    <parent
      link="finger1link1" />
    <child
      link="finger1link2" />
    <axis
      xyz="0 0 1" />
  </joint>
  <link
    name="finger2link1">
    <inertial>
      <origin
        xyz="0.045353 -0.015 -9.7145E-17"
        rpy="0 0 0" />
      <mass
        value="0.084502" />
      <inertia
        ixx="1.3498E-05"
        ixy="7.4374E-21"
        ixz="1.0503E-19"
        iyy="7.9847E-05"
        iyz="-4.352E-23"
        izz="7.9679E-05" />
    </inertial>
    <visual>
      <origin
        xyz="0 0 0"
        rpy="0 0 0" />
      <geometry>
        <mesh
          filename="package://hand/meshes/finger2link1.STL" />
      </geometry>
      <material
        name="">
        <color
          rgba="0.79216 0.81961 0.93333 1" />
      </material>
    </visual>
    <collision>
      <origin
        xyz="0 0 0"
        rpy="0 0 0" />
      <geometry>
        <mesh
          filename="package://hand/meshes/finger2link1.STL" />
      </geometry>
    </collision>
  </link>
  <joint
    name="finger2joint1"
    type="continuous">
    <origin
      xyz="0.14041 -0.14788 0.13064"
      rpy="0 -0.39662 0" />
    <parent
      link="base_link" />
    <child
      link="finger2link1" />
    <axis
      xyz="0 1 0" />
  </joint>
  <link
    name="finger2link2">
    <inertial>
      <origin
        xyz="0.0546299311815429 0 0.00800000000000001"
        rpy="0 0 0" />
      <mass
        value="0.0542831853071796" />
      <inertia
        ixx="5.26855009276151E-06"
        ixy="1.19533639512848E-21"
        ixz="-8.66693115415942E-22"
        iyy="6.34128847377856E-05"
        iyz="2.97952309526164E-23"
        izz="6.63653522574407E-05" />
    </inertial>
    <visual>
      <origin
        xyz="0 0 0"
        rpy="0 0 0" />
      <geometry>
        <mesh
          filename="package://hand/meshes/finger2link2.STL" />
      </geometry>
      <material
        name="">
        <color
          rgba="0.792156862745098 0.819607843137255 0.933333333333333 1" />
      </material>
    </visual>
    <collision>
      <origin
        xyz="0 0 0"
        rpy="0 0 0" />
      <geometry>
        <mesh
          filename="package://hand/meshes/finger2link2.STL" />
      </geometry>
    </collision>
  </link>
  <joint
    name="finger2joint2"
    type="continuous">
    <origin
      xyz="0.1 -0.005 0"
      rpy="1.5707963267949 0.396621036490494 0" />
    <parent
      link="finger2link1" />
    <child
      link="finger2link2" />
    <axis
      xyz="0 0 1" />
  </joint>
  <link
    name="finger3link1">
    <inertial>
      <origin
        xyz="0.045353 -0.015211 -5.8287E-16"
        rpy="0 0 0" />
      <mass
        value="0.084502" />
      <inertia
        ixx="1.3498E-05"
        ixy="4.078E-21"
        ixz="1.7364E-20"
        iyy="7.9847E-05"
        iyz="-6.3724E-22"
        izz="7.9679E-05" />
    </inertial>
    <visual>
      <origin
        xyz="0 0 0"
        rpy="0 0 0" />
      <geometry>
        <mesh
          filename="package://hand/meshes/finger3link1.STL" />
      </geometry>
      <material
        name="">
        <color
          rgba="0.79216 0.81961 0.93333 1" />
      </material>
    </visual>
    <collision>
      <origin
        xyz="0 0 0"
        rpy="0 0 0" />
      <geometry>
        <mesh
          filename="package://hand/meshes/finger3link1.STL" />
      </geometry>
    </collision>
  </link>
  <joint
    name="finger3joint1"
    type="continuous">
    <origin
      xyz="0.14041 -0.097876 0.13064"
      rpy="0 -0.54322 0" />
    <parent
      link="base_link" />
    <child
      link="finger3link1" />
    <axis
      xyz="0 1 0" />
  </joint>
  <link
    name="finger3link2">
    <inertial>
      <origin
        xyz="0.05463 -1.1102E-16 0.008"
        rpy="0 0 0" />
      <mass
        value="0.054283" />
      <inertia
        ixx="5.2686E-06"
        ixy="6.3316E-20"
        ixz="-6.7548E-22"
        iyy="6.3413E-05"
        iyz="3.317E-22"
        izz="6.6365E-05" />
    </inertial>
    <visual>
      <origin
        xyz="0 0 0"
        rpy="0 0 0" />
      <geometry>
        <mesh
          filename="package://hand/meshes/finger3link2.STL" />
      </geometry>
      <material
        name="">
        <color
          rgba="0.79216 0.81961 0.93333 1" />
      </material>
    </visual>
    <collision>
      <origin
        xyz="0 0 0"
        rpy="0 0 0" />
      <geometry>
        <mesh
          filename="package://hand/meshes/finger3link2.STL" />
      </geometry>
    </collision>
  </link>
  <joint
    name="finger3joint2"
    type="continuous">
    <origin
      xyz="0.0999999999999996 -0.00521081779341741 0"
      rpy="1.5707963267949 1.00382067087895 0" />
    <parent
      link="finger3link1" />
    <child
      link="finger3link2" />
    <axis
      xyz="0 0 1" />
  </joint>
  <link
    name="finger4link1">
    <inertial>
      <origin
        xyz="0 0 0"
        rpy="0 0 0" />
      <mass
        value="0" />
      <inertia
        ixx="0"
        ixy="0"
        ixz="0"
        iyy="0"
        iyz="0"
        izz="0" />
    </inertial>
    <visual>
      <origin
        xyz="0 0 0"
        rpy="0 0 0" />
      <geometry>
        <mesh
          filename="package://hand/meshes/finger4link1.STL" />
      </geometry>
      <material
        name="">
        <color
          rgba="1 1 1 1" />
      </material>
    </visual>
    <collision>
      <origin
        xyz="0 0 0"
        rpy="0 0 0" />
      <geometry>
        <mesh
          filename="package://hand/meshes/finger4link1.STL" />
      </geometry>
    </collision>
  </link>
  <joint
    name="finger4joint1"
    type="continuous">
    <origin
      xyz="0.140408435944426 -0.048087112246984 0.130639070101562"
      rpy="0 0.162603665267156 0" />
    <parent
      link="base_link" />
    <child
      link="finger4link1" />
    <axis
      xyz="0 1 0" />
  </joint>
  <link
    name="finger4link2">
    <inertial>
      <origin
        xyz="0.05463 0 0.008"
        rpy="0 0 0" />
      <mass
        value="0.054283" />
      <inertia
        ixx="5.2686E-06"
        ixy="1.7702E-21"
        ixz="6.2403E-22"
        iyy="6.3413E-05"
        iyz="2.1176E-22"
        izz="6.6365E-05" />
    </inertial>
    <visual>
      <origin
        xyz="0 0 0"
        rpy="0 0 0" />
      <geometry>
        <mesh
          filename="package://hand/meshes/finger4link2.STL" />
      </geometry>
      <material
        name="">
        <color
          rgba="0.79216 0.81961 0.93333 1" />
      </material>
    </visual>
    <collision>
      <origin
        xyz="0 0 0"
        rpy="0 0 0" />
      <geometry>
        <mesh
          filename="package://hand/meshes/finger4link2.STL" />
      </geometry>
    </collision>
  </link>
  <joint
    name="finger4joint2"
    type="continuous">
    <origin
      xyz="0.0999999999999997 -0.00231983302013206 0"
      rpy="1.5707963267949 -0.162603665267155 0" />
    <parent
      link="finger4link1" />
    <child
      link="finger4link2" />
    <axis
      xyz="0 0 1" />
  </joint>
</robot>